<?xml version="1.0" ?>
<!-- Generated using onshape-to-robot -->
<!-- Onshape https://cad.onshape.com/documents/f2e60be8d52c5137ae6cfd25/w/45859e4dbafc73eedc6eb2b0/e/3845b2cc23ef6a34e1afbb9d -->
<robot name="sbr_description">
  <!-- Link base_link -->
  <link name="base_link">
    <inertial>
      <origin xyz="0 0 0" rpy="0 0 0"/>
      <mass value="1e-09"/>
      <inertia ixx="1e-09" ixy="0" ixz="0" iyy="1e-09" iyz="0" izz="1e-09"/>
    </inertial>
  </link>
  <!-- Link camera -->
  <link name="camera">
    <inertial>
      <origin xyz="-0.0378203 0.00456874 0.0245667" rpy="0 0 0"/>
      <mass value="1.523"/>
      <inertia ixx="0.00586627" ixy="2.22208e-05" ixz="2.4478e-05" iyy="0.00690954" iyz="-0.000252623" izz="0.00284535"/>
    </inertial>
    <!-- Part camera_parts -->
    <visual>
      <origin xyz="-0.0378203 0.00456874 0.0245667" rpy="0 -0 0"/>
      <geometry>
        <mesh filename="package://assets/merged/camera_visual.stl"/>
      </geometry>
      <material name="camera_parts_material">
        <color rgba="0.618601 0.67347 0.693793 0.881812"/>
      </material>
    </visual>
    <collision>
      <origin xyz="-0.0378203 0.00456874 0.0245667" rpy="0 -0 0"/>
      <geometry>
        <mesh filename="package://assets/merged/camera_collision.stl"/>
      </geometry>
    </collision>
  </link>
  <!-- Link left_wheel -->
  <link name="left_wheel">
    <inertial>
      <origin xyz="-3.41977e-11 2.60908e-11 -0.0178081" rpy="0 0 0"/>
      <mass value="0.0475"/>
      <inertia ixx="2.01071e-05" ixy="1.9814e-10" ixz="1.31082e-14" iyy="2.01074e-05" iyz="-1.03431e-14" izz="3.50442e-05"/>
    </inertial>
    <!-- Part left_wheel_parts -->
    <visual>
      <origin xyz="-3.41977e-11 2.60909e-11 -0.0178081" rpy="1.5708 1.5708 0"/>
      <geometry>
        <mesh filename="package://assets/merged/left_wheel_visual.stl"/>
      </geometry>
      <material name="left_wheel_parts_material">
        <color rgba="0.647059 0.647059 0.647059 1"/>
      </material>
    </visual>
    <collision>
      <origin xyz="-3.41977e-11 2.60909e-11 -0.0178081" rpy="1.5708 1.5708 0"/>
      <geometry>
        <mesh filename="package://assets/merged/left_wheel_collision.stl"/>
      </geometry>
    </collision>
  </link>
  <!-- Joint from camera to left_wheel -->
  <joint name="left_wheel_joint" type="continuous">
    <origin xyz="0.0265233 0.00796397 -0.0669234" rpy="-1.5708 6.12323e-17 1.5708"/>
    <parent link="camera"/>
    <child link="left_wheel"/>
    <axis xyz="0 0 1"/>
    <limit effort="10" velocity="10"/>
  </joint>
  <!-- Link right_wheel -->
  <link name="right_wheel">
    <inertial>
      <origin xyz="-3.41977e-11 2.60908e-11 -0.0178081" rpy="0 0 0"/>
      <mass value="0.0475"/>
      <inertia ixx="2.01071e-05" ixy="1.9814e-10" ixz="1.31082e-14" iyy="2.01074e-05" iyz="-1.03431e-14" izz="3.50442e-05"/>
    </inertial>
    <!-- Part right_wheel_parts -->
    <visual>
      <origin xyz="-3.41977e-11 2.60909e-11 -0.0178081" rpy="1.5708 -1.5708 0"/>
      <geometry>
        <mesh filename="package://assets/merged/right_wheel_visual.stl"/>
      </geometry>
      <material name="right_wheel_parts_material">
        <color rgba="0.647059 0.647059 0.647059 1"/>
      </material>
    </visual>
    <collision>
      <origin xyz="-3.41977e-11 2.60909e-11 -0.0178081" rpy="1.5708 -1.5708 0"/>
      <geometry>
        <mesh filename="package://assets/merged/right_wheel_collision.stl"/>
      </geometry>
    </collision>
  </link>
  <!-- Joint from camera to right_wheel -->
  <joint name="right_wheel_joint" type="continuous">
    <origin xyz="-0.100577 0.00796397 -0.0669234" rpy="-1.5708 -6.12323e-17 -1.5708"/>
    <parent link="camera"/>
    <child link="right_wheel"/>
    <axis xyz="0 0 1"/>
    <limit effort="10" velocity="10"/>
  </joint>
  <!-- Joint from base_link to camera -->
  <joint name="base_link_to_camera" type="fixed">
    <origin xyz="0 0 0" rpy="0 -0 0"/>
    <parent link="base_link"/>
    <child link="camera"/>
    <axis xyz="0 0 1"/>
    <limit effort="10" velocity="10"/>
  </joint>
</robot>
